2017-07-07 16:45:20  task  INFO       rule: txt\f_dob_gender_middle.txt; pairs number: 7198
2017-07-07 16:45:26  task  INFO       rule: txt\f_l_ssn_phone.txt; pairs number: 2901
2017-07-07 16:45:32  task  INFO       rule: txt\f_gender_ssn_phone.txt; pairs number: 3024
2017-07-07 16:45:37  task  INFO       rule: txt\f_l_ssn_mid.txt; pairs number: 2588
2017-07-07 16:45:51  task  INFO       rule: txt\f_l_dob_mid.txt; pairs number: 7680
2017-07-07 16:45:54  task  INFO       rule: txt\l_ssn_addr_phone.txt; pairs number: 935
2017-07-07 16:46:14  task  INFO       rule: txt\l_dob_gender_ssn.txt; pairs number: 11573
2017-07-07 16:46:17  task  INFO       rule: txt\f_dob_gender_email.txt; pairs number: 5
2017-07-07 16:46:34  task  INFO       rule: txt\f_l_gender_mid.txt; pairs number: 9364
2017-07-07 16:46:39  task  INFO       rule: txt\l_dob_ssn_phone.txt; pairs number: 2453
2017-07-07 16:46:58  task  INFO       rule: txt\f_l_dob_addr.txt; pairs number: 10753
2017-07-07 16:47:30  task  INFO       rule: txt\f_l_dob_phone.txt; pairs number: 20215
2017-07-07 16:47:39  task  INFO       rule: txt\l_dob_ssn_addr.txt; pairs number: 4875
2017-07-07 16:47:45  task  INFO       rule: txt\dob_ssn_gender_phone.txt; pairs number: 2578
2017-07-07 16:47:54  task  INFO       rule: txt\f_l_ssn_addr.txt; pairs number: 4500
2017-07-07 16:48:00  task  INFO       rule: txt\gender_ssn_addr_phone.txt; pairs number: 2578
2017-07-07 16:48:03  task  INFO       rule: txt\f_dob_ssn_email.txt; pairs number: 0
2017-07-07 16:48:24  task  INFO       rule: txt\l_dob_gender_addr.txt; pairs number: 11523
2017-07-07 16:48:32  task  INFO       rule: txt\dob_ssn_gender_address.txt; pairs number: 4447
2017-07-07 16:48:40  task  INFO       rule: txt\l_ssn_gender_addr.txt; pairs number: 3977
2017-07-07 16:48:49  task  INFO       rule: txt\f_l_phone_middle.txt; pairs number: 4488
2017-07-07 16:49:01  task  INFO       rule: txt\f_l_addr_phone.txt; pairs number: 6433
2017-07-07 16:49:10  task  INFO       rule: txt\f_gender_ssn_addr.txt; pairs number: 4668
2017-07-07 16:49:16  task  INFO       rule: txt\l_ssn_gender_phone.txt; pairs number: 2502
2017-07-07 16:49:20  task  INFO       rule: txt\f_dob_addr_email.txt; pairs number: 0
2017-07-07 16:49:24  task  INFO       rule: txt\f_gender_ssn_email.txt; pairs number: 0
2017-07-07 16:49:28  task  INFO       rule: txt\f_dob_phone_email.txt; pairs number: 0
2017-07-07 16:49:35  task  INFO       rule: txt\f_l_addr_middle.txt; pairs number: 2611
2017-07-07 16:50:13  task  INFO       rule: txt\l_dob_gender_phone.txt; pairs number: 22566
2017-07-26 10:40:06  task  INFO       rule: txt\3_fields_process_address\l_ssn_gender.txt; pairs number: 17177
2017-07-26 10:40:51  task  INFO       rule: txt\3_fields_process_address\l_dob_ssn.txt; pairs number: 21008
2017-07-26 10:40:54  task  INFO       rule: txt\3_fields_process_address\f_dob_email.txt; pairs number: 10
2017-07-29 10:46:49  task  INFO       rule: txt\3_fields_process_address\dob_ssn_gender.txt; pairs number: 32220
2017-07-29 10:47:45  task  INFO       rule: txt\3_fields_process_address\f_gender_ssn.txt; pairs number: 34754
2017-07-29 11:06:28  task  INFO       rule: txt\3_fields_process_address\f_l_gender.txt; pairs number: 1408314
2017-07-29 11:07:38  task  INFO       rule: txt\3_fields_process_address\l_gender_dob.txt; pairs number: 84238
2017-07-29 11:07:46  task  INFO       rule: txt\3_fields_process_address\dob_ssn_phone.txt; pairs number: 6758
2017-07-29 11:07:54  task  INFO       rule: txt\3_fields_process_address\ssn_gender_phone.txt; pairs number: 6816
2017-07-29 11:08:23  task  INFO       rule: txt\3_fields_process_address\l_dob_ssn.txt; pairs number: 33216
2017-07-29 11:08:51  task  INFO       rule: txt\3_fields_process_address\f_l_ssn.txt; pairs number: 32612
2017-07-29 11:08:55  task  INFO       rule: txt\3_fields_process_address\f_dob_email.txt; pairs number: 10
2017-07-29 11:09:14  task  INFO       rule: txt\3_fields_process_address\f_l_middle.txt; pairs number: 20986
2017-07-29 11:09:22  task  INFO       rule: txt\3_fields_process_address\l_ssn_phone.txt; pairs number: 6670
2017-07-29 11:09:51  task  INFO       rule: txt\3_fields_process_address\dob_ssn_gender.txt; pairs number: 32220
2017-07-29 11:10:52  task  INFO       rule: txt\3_fields_process_address\f_l_dob.txt; pairs number: 74476
2017-07-29 11:11:18  task  INFO       rule: txt\3_fields_process_address\l_ssn_gender.txt; pairs number: 28426
2017-07-29 11:13:15  task  INFO       rule: txt\3_fields_process_address\f_dob_gender.txt; pairs number: 138100
2017-07-29 11:13:57  task  INFO       rule: txt\3_fields_process_address\f_l_phone.txt; pairs number: 44294
2017-07-29 16:06:45  sqlalchemy.pool.QueuePool ERROR      Exception closing connection <cx_Oracle.Connection to alexgre@(DESCRIPTION=(ADDRESS_LIST=(ADDRESS=(PROTOCOL=TCP)(HOST=temp1.clx2hx01phun.us-east-1.rds.amazonaws.com)(PORT=1521)))(CONNECT_DATA=(SID=ORCL)))>
Traceback (most recent call last):
  File "D:\Python3.5.3\lib\site-packages\sqlalchemy\engine\base.py", line 721, in _commit_impl
    self.engine.dialect.do_commit(self.connection)
  File "D:\Python3.5.3\lib\site-packages\sqlalchemy\engine\default.py", line 443, in do_commit
    dbapi_connection.commit()
cx_Oracle.OperationalError: ORA-03113: end-of-file on communication channel
Process ID: 12677
Session ID: 36 Serial number: 37607


The above exception was the direct cause of the following exception:

Traceback (most recent call last):
  File "D:\Python3.5.3\lib\site-packages\sqlalchemy\engine\base.py", line 1393, in _handle_dbapi_exception
    exc_info
  File "D:\Python3.5.3\lib\site-packages\sqlalchemy\util\compat.py", line 203, in raise_from_cause
    reraise(type(exception), exception, tb=exc_tb, cause=cause)
  File "D:\Python3.5.3\lib\site-packages\sqlalchemy\util\compat.py", line 186, in reraise
    raise value.with_traceback(tb)
  File "D:\Python3.5.3\lib\site-packages\sqlalchemy\engine\base.py", line 721, in _commit_impl
    self.engine.dialect.do_commit(self.connection)
  File "D:\Python3.5.3\lib\site-packages\sqlalchemy\engine\default.py", line 443, in do_commit
    dbapi_connection.commit()
sqlalchemy.exc.OperationalError: (cx_Oracle.OperationalError) ORA-03113: end-of-file on communication channel
Process ID: 12677
Session ID: 36 Serial number: 37607


During handling of the above exception, another exception occurred:

Traceback (most recent call last):
  File "D:\Python3.5.3\lib\site-packages\sqlalchemy\pool.py", line 300, in _close_connection
    self._dialect.do_close(connection)
  File "D:\Python3.5.3\lib\site-packages\sqlalchemy\engine\default.py", line 446, in do_close
    dbapi_connection.close()
cx_Oracle.OperationalError: ORA-03114: not connected to ORACLE

2017-07-29 17:09:27  task  INFO       rule: txt\3_fields_process_address\f_dob_gender.txt; pairs number: 138100
2017-07-29 17:09:40  task  INFO       rule: txt\3_fields_process_address\dob_ssn_phone.txt; pairs number: 6758
2017-07-29 17:09:50  task  INFO       rule: txt\3_fields_process_address\l_ssn_phone.txt; pairs number: 6670
2017-07-29 17:09:53  task  INFO       rule: txt\3_fields_process_address\f_dob_email.txt; pairs number: 10
2017-07-29 17:11:11  task  INFO       rule: txt\3_fields_process_address\l_gender_dob.txt; pairs number: 84238
2017-07-29 17:11:48  task  INFO       rule: txt\3_fields_process_address\f_gender_ssn.txt; pairs number: 34754
2017-07-29 17:12:21  task  INFO       rule: txt\3_fields_process_address\f_l_ssn.txt; pairs number: 32612
2017-07-29 17:12:34  task  INFO       rule: txt\3_fields_process_address\ssn_gender_phone.txt; pairs number: 6816
2017-07-29 17:13:26  task  INFO       rule: txt\3_fields_process_address\f_l_phone.txt; pairs number: 44294
2017-07-29 17:13:48  task  INFO       rule: txt\3_fields_process_address\f_l_middle.txt; pairs number: 20986
2017-07-29 17:15:02  task  INFO       rule: txt\3_fields_process_address\f_l_dob.txt; pairs number: 74476
2017-07-29 17:15:38  task  INFO       rule: txt\3_fields_process_address\l_dob_ssn.txt; pairs number: 33216
2017-07-29 17:16:11  task  INFO       rule: txt\3_fields_process_address\dob_ssn_gender.txt; pairs number: 32220
2017-07-29 17:16:41  task  INFO       rule: txt\3_fields_process_address\l_ssn_gender.txt; pairs number: 28426
2017-07-29 19:09:35  task  INFO       rule: txt\3_fields_process_address\dob_ssn_phone.txt; pairs number: 6758
2017-07-29 19:10:21  task  INFO       rule: txt\3_fields_process_address\f_l_phone.txt; pairs number: 44294
2017-07-29 19:10:55  task  INFO       rule: txt\3_fields_process_address\f_l_ssn.txt; pairs number: 32612
2017-07-29 19:13:00  task  INFO       rule: txt\3_fields_process_address\f_dob_gender.txt; pairs number: 138100
2017-07-29 19:14:13  task  INFO       rule: txt\3_fields_process_address\f_l_dob.txt; pairs number: 74476
2017-07-29 19:14:24  task  INFO       rule: txt\3_fields_process_address\l_ssn_phone.txt; pairs number: 6670
2017-07-29 19:14:29  task  INFO       rule: txt\3_fields_process_address\f_dob_email.txt; pairs number: 10
2017-07-29 19:14:51  task  INFO       rule: txt\3_fields_process_address\f_l_middle.txt; pairs number: 20986
2017-07-29 19:15:25  task  INFO       rule: txt\3_fields_process_address\l_dob_ssn.txt; pairs number: 33216
2017-07-29 19:16:00  task  INFO       rule: txt\3_fields_process_address\dob_ssn_gender.txt; pairs number: 32220
2017-07-29 19:17:18  task  INFO       rule: txt\3_fields_process_address\l_gender_dob.txt; pairs number: 84238
2017-07-29 19:17:55  task  INFO       rule: txt\3_fields_process_address\f_gender_ssn.txt; pairs number: 34754
2017-07-29 19:18:25  task  INFO       rule: txt\3_fields_process_address\l_ssn_gender.txt; pairs number: 28426
2017-07-29 19:18:37  task  INFO       rule: txt\3_fields_process_address\ssn_gender_phone.txt; pairs number: 6816
2017-08-03 17:28:38  task  INFO       rule: txt\3_fields_process_name\first_name\l_dob_ssn.txt; pairs number: 33216
2017-08-03 17:28:41  task  INFO       rule: txt\3_fields_process_name\last_name\f_gender_ssn.txt; pairs number: 34754
2017-08-03 17:28:50  task  INFO       rule: txt\3_fields_process_name\first_name\gender_ssn_middle.txt; pairs number: 4666
2017-08-03 17:29:01  task  INFO       rule: txt\3_fields_process_name\last_name\f_addr_phone.txt; pairs number: 13446
2017-08-03 17:29:37  task  INFO       rule: txt\3_fields_process_name\last_name\dob_gender_middle.txt; pairs number: 35758
2017-08-03 17:29:51  task  INFO       rule: txt\3_fields_process_name\last_name\gender_ssn_addr.txt; pairs number: 10252
2017-08-03 17:30:27  task  INFO       rule: txt\3_fields_process_name\last_name\dob_gender_ssn.txt; pairs number: 32220
2017-08-03 17:30:38  task  INFO       rule: txt\3_fields_process_name\last_name\dob_ssn_phone.txt; pairs number: 6758
2017-08-03 17:31:25  task  INFO       rule: txt\3_fields_process_name\last_name\dob_gender_phone.txt; pairs number: 47360
2017-08-03 17:31:51  task  INFO       rule: txt\3_fields_process_name\last_name\f_dob_addr.txt; pairs number: 24048
2017-08-03 17:32:10  task  INFO       rule: txt\3_fields_process_name\last_name\dob_addr_phone.txt; pairs number: 14618
2017-08-03 17:32:26  task  INFO       rule: txt\3_fields_process_name\last_name\dob_ssn_addr.txt; pairs number: 12072
2017-08-03 17:32:40  task  INFO       rule: txt\3_fields_process_name\last_name\f_ssn_addr.txt; pairs number: 11060
2017-08-03 17:35:12  task  INFO       rule: txt\3_fields_process_name\last_name\f_dob_addr.txt; pairs number: 24048
2017-08-03 17:35:40  task  INFO       rule: txt\3_fields_process_name\first_name\l_address_phone.txt; pairs number: 52866
2017-08-03 17:36:02  task  INFO       rule: txt\3_fields_process_name\last_name\f_dob_phone.txt; pairs number: 42308
2017-08-03 17:36:02  task  INFO       rule: txt\3_fields_process_name\first_name\l_dob_middle.txt; pairs number: 17870
2017-08-03 17:36:19  task  INFO       rule: txt\3_fields_process_name\last_name\ssn_address_phone.txt; pairs number: 8544
2017-08-03 17:36:39  task  INFO       rule: txt\3_fields_process_name\last_name\f_addr_phone.txt; pairs number: 13446
2017-08-03 17:36:42  task  INFO       rule: txt\3_fields_process_name\first_name\dob_gender_ssn.txt; pairs number: 32220
2017-08-03 17:36:53  task  INFO       rule: txt\3_fields_process_name\last_name\f_ssn_phone.txt; pairs number: 7348
2017-08-03 17:36:53  task  INFO       rule: txt\3_fields_process_name\first_name\l_ssn_middle.txt; pairs number: 5722
2017-08-03 17:37:11  task  INFO       rule: txt\3_fields_process_name\last_name\gender_ssn_addr.txt; pairs number: 10252
2017-08-03 17:37:46  task  INFO       rule: txt\3_fields_process_name\last_name\dob_gender_ssn.txt; pairs number: 32220
2017-08-03 17:37:47  task  INFO       rule: txt\3_fields_process_name\first_name\gender_dob_phone.txt; pairs number: 47360
2017-08-03 17:37:59  task  INFO       rule: txt\3_fields_process_name\first_name\gender_ssn_middle.txt; pairs number: 4666
2017-08-03 17:38:44  task  INFO       rule: txt\3_fields_process_name\last_name\f_gender_ssn.txt; pairs number: 34754
2017-08-03 17:39:13  task  INFO       rule: txt\3_fields_process_name\last_name\f_ssn_addr.txt; pairs number: 11060
2017-08-03 17:39:37  task  INFO       rule: txt\3_fields_process_name\first_name\gender_ssn_address.txt; pairs number: 53504
2017-08-03 17:39:43  task  INFO       rule: txt\3_fields_process_name\last_name\dob_ssn_addr.txt; pairs number: 12072
2017-08-03 17:40:03  task  INFO       rule: txt\3_fields_process_name\first_name\gender_ssn_phone.txt; pairs number: 6816
2017-08-03 17:40:07  task  INFO       rule: txt\3_fields_process_name\last_name\dob_ssn_phone.txt; pairs number: 6758
2017-08-03 17:40:25  task  INFO       rule: txt\3_fields_process_name\first_name\l_ssn_phone.txt; pairs number: 6670
2017-08-03 17:40:33  task  INFO       rule: txt\3_fields_process_name\last_name\gender_ssn_phone.txt; pairs number: 6816
2017-08-03 17:41:07  task  INFO       rule: txt\3_fields_process_name\last_name\dob_addr_phone.txt; pairs number: 14618
2017-08-03 17:41:35  task  INFO       rule: txt\3_fields_process_name\first_name\l_dob_ssn.txt; pairs number: 33216
2017-08-03 17:41:54  task  INFO       rule: txt\3_fields_process_name\last_name\dob_gender_middle.txt; pairs number: 35758
2017-08-03 17:42:40  task  INFO       rule: txt\3_fields_process_name\last_name\dob_gender_phone.txt; pairs number: 47360
2017-08-03 17:42:57  task  INFO       rule: txt\3_fields_process_name\first_name\l_dob_gender.txt; pairs number: 84238
2017-08-03 17:43:03  task  INFO       rule: txt\3_fields_process_name\first_name\dob_gender_email.txt; pairs number: 246
2017-08-03 17:43:18  task  INFO       rule: txt\3_fields_process_name\first_name\l_ssn_addr.txt; pairs number: 11146
2017-08-03 17:44:04  task  INFO       rule: txt\3_fields_process_name\first_name\l_dob_phone.txt; pairs number: 48336
2017-08-03 17:44:09  task  INFO       rule: txt\3_fields_process_name\first_name\dob_ssn_email.txt; pairs number: 0
2017-08-03 17:44:36  task  INFO       rule: txt\3_fields_process_name\first_name\l_dob_addr.txt; pairs number: 26790
2017-08-03 17:45:05  task  INFO       rule: txt\3_fields_process_name\first_name\l_gender_ssn.txt; pairs number: 28426
2017-08-03 20:53:42  task  INFO       rule: txt\3_fields_process_name\first_name\gender_dob_address.txt; pairs number: 14407912
2017-08-04 20:01:03  task  INFO       rule: txt\3_fields_process_name\first_name\l_ssn_phone.txt; pairs number: 6670
2017-08-04 20:03:51  task  INFO       rule: txt\3_fields_process_name\first_name\gender_ssn_address.txt; pairs number: 53504
2017-08-04 20:03:54  task  INFO       rule: txt\3_fields_process_name\first_name\dob_ssn_email.txt; pairs number: 0
2017-08-04 20:04:05  task  INFO       rule: txt\3_fields_process_name\first_name\gender_ssn_phone.txt; pairs number: 6816
2017-08-04 20:04:09  task  INFO       rule: txt\3_fields_process_name\first_name\dob_gender_email.txt; pairs number: 246
2017-08-04 20:04:59  task  INFO       rule: txt\3_fields_process_name\first_name\gender_dob_phone.txt; pairs number: 47360
2017-08-04 20:05:13  task  INFO       rule: txt\3_fields_process_name\first_name\l_ssn_addr.txt; pairs number: 11146
2017-08-04 20:05:43  task  INFO       rule: txt\3_fields_process_name\first_name\l_dob_addr.txt; pairs number: 26790
2017-08-04 20:05:49  task  INFO       rule: txt\3_fields_process_name\first_name\gender_ssn_middle.txt; pairs number: 4666
2017-08-04 20:06:25  task  INFO       rule: txt\3_fields_process_name\first_name\l_dob_ssn.txt; pairs number: 33216
2017-08-04 20:07:21  task  INFO       rule: txt\3_fields_process_name\first_name\l_address_phone.txt; pairs number: 52866
2017-08-04 20:07:40  task  INFO       rule: txt\3_fields_process_name\first_name\l_dob_middle.txt; pairs number: 17870
2017-08-04 20:08:30  task  INFO       rule: txt\3_fields_process_name\first_name\l_dob_phone.txt; pairs number: 48336
2017-08-04 20:09:01  task  INFO       rule: txt\3_fields_process_name\first_name\l_gender_ssn.txt; pairs number: 28426
2017-08-04 20:13:15  sqlalchemy.pool.QueuePool ERROR      Exception during reset or similar
Traceback (most recent call last):
  File "D:\Python3.5.3\lib\site-packages\sqlalchemy\pool.py", line 687, in _finalize_fairy
    fairy._reset(pool)
  File "D:\Python3.5.3\lib\site-packages\sqlalchemy\pool.py", line 829, in _reset
    pool._dialect.do_rollback(self)
  File "D:\Python3.5.3\lib\site-packages\sqlalchemy\engine\default.py", line 440, in do_rollback
    dbapi_connection.rollback()
cx_Oracle.OperationalError: ORA-03113: end-of-file on communication channel
Process ID: 2831
Session ID: 54 Serial number: 1521

2017-08-04 20:13:15  sqlalchemy.pool.QueuePool ERROR      Exception closing connection <cx_Oracle.Connection to alexgre@(DESCRIPTION=(ADDRESS_LIST=(ADDRESS=(PROTOCOL=TCP)(HOST=temp1.clx2hx01phun.us-east-1.rds.amazonaws.com)(PORT=1521)))(CONNECT_DATA=(SID=ORCL)))>
Traceback (most recent call last):
  File "D:\Python3.5.3\lib\site-packages\sqlalchemy\pool.py", line 687, in _finalize_fairy
    fairy._reset(pool)
  File "D:\Python3.5.3\lib\site-packages\sqlalchemy\pool.py", line 829, in _reset
    pool._dialect.do_rollback(self)
  File "D:\Python3.5.3\lib\site-packages\sqlalchemy\engine\default.py", line 440, in do_rollback
    dbapi_connection.rollback()
cx_Oracle.OperationalError: ORA-03113: end-of-file on communication channel
Process ID: 2831
Session ID: 54 Serial number: 1521


During handling of the above exception, another exception occurred:

Traceback (most recent call last):
  File "D:\Python3.5.3\lib\site-packages\sqlalchemy\pool.py", line 300, in _close_connection
    self._dialect.do_close(connection)
  File "D:\Python3.5.3\lib\site-packages\sqlalchemy\engine\default.py", line 446, in do_close
    dbapi_connection.close()
cx_Oracle.OperationalError: ORA-03114: not connected to ORACLE

2017-08-07 22:03:35  task  ERROR      name 'functools' is not defined
2017-08-07 22:03:35  task  ERROR      name 'functools' is not defined
2017-08-07 22:03:35  task  ERROR      name 'functools' is not defined
2017-08-07 22:03:35  task  ERROR      name 'functools' is not defined
2017-08-07 22:03:35  task  ERROR      name 'functools' is not defined
2017-08-07 22:03:35  task  ERROR      name 'functools' is not defined
2017-08-07 22:03:35  task  ERROR      name 'functools' is not defined
2017-08-07 22:03:35  task  ERROR      name 'functools' is not defined
2017-08-07 22:03:35  task  ERROR      name 'functools' is not defined
2017-08-07 22:03:35  task  ERROR      name 'functools' is not defined
2017-08-07 22:03:35  task  ERROR      name 'functools' is not defined
2017-08-07 22:03:35  task  ERROR      name 'functools' is not defined
2017-08-07 22:03:35  task  ERROR      name 'functools' is not defined
2017-08-07 22:03:35  task  ERROR      name 'functools' is not defined
2017-08-07 22:03:35  task  ERROR      name 'functools' is not defined
2017-08-07 22:03:35  task  ERROR      name 'functools' is not defined
2017-08-07 22:03:35  task  ERROR      name 'functools' is not defined
2017-08-07 22:03:35  task  ERROR      name 'functools' is not defined
2017-08-07 22:03:35  task  ERROR      name 'functools' is not defined
2017-08-07 22:03:35  task  ERROR      name 'functools' is not defined
2017-08-07 22:03:35  task  ERROR      name 'functools' is not defined
2017-08-07 22:03:35  task  ERROR      name 'functools' is not defined
2017-08-07 22:03:35  task  ERROR      name 'functools' is not defined
2017-08-07 22:09:17  task  ERROR      name 'functools' is not defined
2017-08-07 22:09:17  task  ERROR      name 'functools' is not defined
2017-08-07 22:09:17  task  ERROR      name 'functools' is not defined
2017-08-07 22:09:17  task  ERROR      name 'functools' is not defined
2017-08-07 22:09:17  task  ERROR      name 'functools' is not defined
2017-08-07 22:09:17  task  ERROR      name 'functools' is not defined
2017-08-07 22:09:17  task  ERROR      name 'functools' is not defined
2017-08-07 22:09:17  task  ERROR      name 'functools' is not defined
2017-08-07 22:09:17  task  ERROR      name 'functools' is not defined
2017-08-07 22:09:17  task  ERROR      name 'functools' is not defined
2017-08-07 22:09:17  task  ERROR      name 'functools' is not defined
2017-08-07 22:09:17  task  ERROR      name 'functools' is not defined
2017-08-07 22:09:17  task  ERROR      name 'functools' is not defined
2017-08-07 22:09:17  task  ERROR      name 'functools' is not defined
2017-08-07 22:09:17  task  ERROR      name 'functools' is not defined
2017-08-07 22:09:17  task  ERROR      name 'functools' is not defined
2017-08-07 22:09:17  task  ERROR      name 'functools' is not defined
2017-08-07 22:09:17  task  ERROR      name 'functools' is not defined
2017-08-07 22:09:17  task  ERROR      name 'functools' is not defined
2017-08-07 22:09:17  task  ERROR      name 'functools' is not defined
2017-08-07 22:09:17  task  ERROR      name 'functools' is not defined
2017-08-07 22:09:17  task  ERROR      name 'functools' is not defined
2017-08-07 22:09:17  task  ERROR      name 'functools' is not defined
2017-08-07 22:16:01  concurrent.futures ERROR      exception calling callback for <Future at 0x1b8dd630d68 state=finished raised NameError>
concurrent.futures.process._RemoteTraceback: 
"""
Traceback (most recent call last):
  File "D:\Python3.5.3\lib\concurrent\futures\process.py", line 175, in _process_worker
    r = call_item.fn(*call_item.args, **call_item.kwargs)
  File "C:\Users\alex\Desktop\pcm\deterministic method\pipeline\deterministic_rule_pipeline.py", line 62, in store_result_job
    if job == "p":
NameError: name 'job' is not defined
"""

The above exception was the direct cause of the following exception:

Traceback (most recent call last):
  File "D:\Python3.5.3\lib\concurrent\futures\_base.py", line 297, in _invoke_callbacks
    callback(self)
  File "deterministic_rule_pipeline.py", line 86, in store_result_csv_job
    results = future.result()
  File "D:\Python3.5.3\lib\concurrent\futures\_base.py", line 398, in result
    return self.__get_result()
  File "D:\Python3.5.3\lib\concurrent\futures\_base.py", line 357, in __get_result
    raise self._exception
NameError: name 'job' is not defined
2017-08-07 22:16:01  concurrent.futures ERROR      exception calling callback for <Future at 0x1b8dd630c18 state=finished raised NameError>
concurrent.futures.process._RemoteTraceback: 
"""
Traceback (most recent call last):
  File "D:\Python3.5.3\lib\concurrent\futures\process.py", line 175, in _process_worker
    r = call_item.fn(*call_item.args, **call_item.kwargs)
  File "C:\Users\alex\Desktop\pcm\deterministic method\pipeline\deterministic_rule_pipeline.py", line 62, in store_result_job
    if job == "p":
NameError: name 'job' is not defined
"""

The above exception was the direct cause of the following exception:

Traceback (most recent call last):
  File "D:\Python3.5.3\lib\concurrent\futures\_base.py", line 297, in _invoke_callbacks
    callback(self)
  File "deterministic_rule_pipeline.py", line 86, in store_result_csv_job
    results = future.result()
  File "D:\Python3.5.3\lib\concurrent\futures\_base.py", line 398, in result
    return self.__get_result()
  File "D:\Python3.5.3\lib\concurrent\futures\_base.py", line 357, in __get_result
    raise self._exception
NameError: name 'job' is not defined
2017-08-07 22:16:07  concurrent.futures ERROR      exception calling callback for <Future at 0x1b8dd5f00f0 state=finished raised NameError>
concurrent.futures.process._RemoteTraceback: 
"""
Traceback (most recent call last):
  File "D:\Python3.5.3\lib\concurrent\futures\process.py", line 175, in _process_worker
    r = call_item.fn(*call_item.args, **call_item.kwargs)
  File "C:\Users\alex\Desktop\pcm\deterministic method\pipeline\deterministic_rule_pipeline.py", line 62, in store_result_job
    if job == "p":
NameError: name 'job' is not defined
"""

The above exception was the direct cause of the following exception:

Traceback (most recent call last):
  File "D:\Python3.5.3\lib\concurrent\futures\_base.py", line 297, in _invoke_callbacks
    callback(self)
  File "deterministic_rule_pipeline.py", line 86, in store_result_csv_job
    results = future.result()
  File "D:\Python3.5.3\lib\concurrent\futures\_base.py", line 398, in result
    return self.__get_result()
  File "D:\Python3.5.3\lib\concurrent\futures\_base.py", line 357, in __get_result
    raise self._exception
NameError: name 'job' is not defined
2017-08-07 22:16:14  concurrent.futures ERROR      exception calling callback for <Future at 0x1b8dd630eb8 state=finished raised NameError>
concurrent.futures.process._RemoteTraceback: 
"""
Traceback (most recent call last):
  File "D:\Python3.5.3\lib\concurrent\futures\process.py", line 175, in _process_worker
    r = call_item.fn(*call_item.args, **call_item.kwargs)
  File "C:\Users\alex\Desktop\pcm\deterministic method\pipeline\deterministic_rule_pipeline.py", line 62, in store_result_job
    if job == "p":
NameError: name 'job' is not defined
"""

The above exception was the direct cause of the following exception:

Traceback (most recent call last):
  File "D:\Python3.5.3\lib\concurrent\futures\_base.py", line 297, in _invoke_callbacks
    callback(self)
  File "deterministic_rule_pipeline.py", line 86, in store_result_csv_job
    results = future.result()
  File "D:\Python3.5.3\lib\concurrent\futures\_base.py", line 398, in result
    return self.__get_result()
  File "D:\Python3.5.3\lib\concurrent\futures\_base.py", line 357, in __get_result
    raise self._exception
NameError: name 'job' is not defined
2017-08-07 22:16:18  concurrent.futures ERROR      exception calling callback for <Future at 0x1b8dd630e10 state=finished raised NameError>
concurrent.futures.process._RemoteTraceback: 
"""
Traceback (most recent call last):
  File "D:\Python3.5.3\lib\concurrent\futures\process.py", line 175, in _process_worker
    r = call_item.fn(*call_item.args, **call_item.kwargs)
  File "C:\Users\alex\Desktop\pcm\deterministic method\pipeline\deterministic_rule_pipeline.py", line 62, in store_result_job
    if job == "p":
NameError: name 'job' is not defined
"""

The above exception was the direct cause of the following exception:

Traceback (most recent call last):
  File "D:\Python3.5.3\lib\concurrent\futures\_base.py", line 297, in _invoke_callbacks
    callback(self)
  File "deterministic_rule_pipeline.py", line 86, in store_result_csv_job
    results = future.result()
  File "D:\Python3.5.3\lib\concurrent\futures\_base.py", line 398, in result
    return self.__get_result()
  File "D:\Python3.5.3\lib\concurrent\futures\_base.py", line 357, in __get_result
    raise self._exception
NameError: name 'job' is not defined
2017-08-07 22:16:24  concurrent.futures ERROR      exception calling callback for <Future at 0x1b8dd630f60 state=finished raised NameError>
concurrent.futures.process._RemoteTraceback: 
"""
Traceback (most recent call last):
  File "D:\Python3.5.3\lib\concurrent\futures\process.py", line 175, in _process_worker
    r = call_item.fn(*call_item.args, **call_item.kwargs)
  File "C:\Users\alex\Desktop\pcm\deterministic method\pipeline\deterministic_rule_pipeline.py", line 62, in store_result_job
    if job == "p":
NameError: name 'job' is not defined
"""

The above exception was the direct cause of the following exception:

Traceback (most recent call last):
  File "D:\Python3.5.3\lib\concurrent\futures\_base.py", line 297, in _invoke_callbacks
    callback(self)
  File "deterministic_rule_pipeline.py", line 86, in store_result_csv_job
    results = future.result()
  File "D:\Python3.5.3\lib\concurrent\futures\_base.py", line 398, in result
    return self.__get_result()
  File "D:\Python3.5.3\lib\concurrent\futures\_base.py", line 357, in __get_result
    raise self._exception
NameError: name 'job' is not defined
2017-08-07 22:16:27  concurrent.futures ERROR      exception calling callback for <Future at 0x1b8dd63f048 state=finished raised NameError>
concurrent.futures.process._RemoteTraceback: 
"""
Traceback (most recent call last):
  File "D:\Python3.5.3\lib\concurrent\futures\process.py", line 175, in _process_worker
    r = call_item.fn(*call_item.args, **call_item.kwargs)
  File "C:\Users\alex\Desktop\pcm\deterministic method\pipeline\deterministic_rule_pipeline.py", line 62, in store_result_job
    if job == "p":
NameError: name 'job' is not defined
"""

The above exception was the direct cause of the following exception:

Traceback (most recent call last):
  File "D:\Python3.5.3\lib\concurrent\futures\_base.py", line 297, in _invoke_callbacks
    callback(self)
  File "deterministic_rule_pipeline.py", line 86, in store_result_csv_job
    results = future.result()
  File "D:\Python3.5.3\lib\concurrent\futures\_base.py", line 398, in result
    return self.__get_result()
  File "D:\Python3.5.3\lib\concurrent\futures\_base.py", line 357, in __get_result
    raise self._exception
NameError: name 'job' is not defined
2017-08-07 22:16:29  concurrent.futures ERROR      exception calling callback for <Future at 0x1b8dd630cc0 state=finished raised NameError>
concurrent.futures.process._RemoteTraceback: 
"""
Traceback (most recent call last):
  File "D:\Python3.5.3\lib\concurrent\futures\process.py", line 175, in _process_worker
    r = call_item.fn(*call_item.args, **call_item.kwargs)
  File "C:\Users\alex\Desktop\pcm\deterministic method\pipeline\deterministic_rule_pipeline.py", line 62, in store_result_job
    if job == "p":
NameError: name 'job' is not defined
"""

The above exception was the direct cause of the following exception:

Traceback (most recent call last):
  File "D:\Python3.5.3\lib\concurrent\futures\_base.py", line 297, in _invoke_callbacks
    callback(self)
  File "deterministic_rule_pipeline.py", line 86, in store_result_csv_job
    results = future.result()
  File "D:\Python3.5.3\lib\concurrent\futures\_base.py", line 398, in result
    return self.__get_result()
  File "D:\Python3.5.3\lib\concurrent\futures\_base.py", line 357, in __get_result
    raise self._exception
NameError: name 'job' is not defined
2017-08-07 22:16:30  concurrent.futures ERROR      exception calling callback for <Future at 0x1b8dd63f0f0 state=finished raised NameError>
concurrent.futures.process._RemoteTraceback: 
"""
Traceback (most recent call last):
  File "D:\Python3.5.3\lib\concurrent\futures\process.py", line 175, in _process_worker
    r = call_item.fn(*call_item.args, **call_item.kwargs)
  File "C:\Users\alex\Desktop\pcm\deterministic method\pipeline\deterministic_rule_pipeline.py", line 62, in store_result_job
    if job == "p":
NameError: name 'job' is not defined
"""

The above exception was the direct cause of the following exception:

Traceback (most recent call last):
  File "D:\Python3.5.3\lib\concurrent\futures\_base.py", line 297, in _invoke_callbacks
    callback(self)
  File "deterministic_rule_pipeline.py", line 86, in store_result_csv_job
    results = future.result()
  File "D:\Python3.5.3\lib\concurrent\futures\_base.py", line 398, in result
    return self.__get_result()
  File "D:\Python3.5.3\lib\concurrent\futures\_base.py", line 357, in __get_result
    raise self._exception
NameError: name 'job' is not defined
2017-08-07 22:16:41  concurrent.futures ERROR      exception calling callback for <Future at 0x1b8dd63f198 state=finished raised NameError>
concurrent.futures.process._RemoteTraceback: 
"""
Traceback (most recent call last):
  File "D:\Python3.5.3\lib\concurrent\futures\process.py", line 175, in _process_worker
    r = call_item.fn(*call_item.args, **call_item.kwargs)
  File "C:\Users\alex\Desktop\pcm\deterministic method\pipeline\deterministic_rule_pipeline.py", line 62, in store_result_job
    if job == "p":
NameError: name 'job' is not defined
"""

The above exception was the direct cause of the following exception:

Traceback (most recent call last):
  File "D:\Python3.5.3\lib\concurrent\futures\_base.py", line 297, in _invoke_callbacks
    callback(self)
  File "deterministic_rule_pipeline.py", line 86, in store_result_csv_job
    results = future.result()
  File "D:\Python3.5.3\lib\concurrent\futures\_base.py", line 398, in result
    return self.__get_result()
  File "D:\Python3.5.3\lib\concurrent\futures\_base.py", line 357, in __get_result
    raise self._exception
NameError: name 'job' is not defined
2017-08-07 22:16:43  concurrent.futures ERROR      exception calling callback for <Future at 0x1b8dd63f2e8 state=finished raised NameError>
concurrent.futures.process._RemoteTraceback: 
"""
Traceback (most recent call last):
  File "D:\Python3.5.3\lib\concurrent\futures\process.py", line 175, in _process_worker
    r = call_item.fn(*call_item.args, **call_item.kwargs)
  File "C:\Users\alex\Desktop\pcm\deterministic method\pipeline\deterministic_rule_pipeline.py", line 62, in store_result_job
    if job == "p":
NameError: name 'job' is not defined
"""

The above exception was the direct cause of the following exception:

Traceback (most recent call last):
  File "D:\Python3.5.3\lib\concurrent\futures\_base.py", line 297, in _invoke_callbacks
    callback(self)
  File "deterministic_rule_pipeline.py", line 86, in store_result_csv_job
    results = future.result()
  File "D:\Python3.5.3\lib\concurrent\futures\_base.py", line 398, in result
    return self.__get_result()
  File "D:\Python3.5.3\lib\concurrent\futures\_base.py", line 357, in __get_result
    raise self._exception
NameError: name 'job' is not defined
2017-08-07 22:16:45  concurrent.futures ERROR      exception calling callback for <Future at 0x1b8dd63f240 state=finished raised NameError>
concurrent.futures.process._RemoteTraceback: 
"""
Traceback (most recent call last):
  File "D:\Python3.5.3\lib\concurrent\futures\process.py", line 175, in _process_worker
    r = call_item.fn(*call_item.args, **call_item.kwargs)
  File "C:\Users\alex\Desktop\pcm\deterministic method\pipeline\deterministic_rule_pipeline.py", line 62, in store_result_job
    if job == "p":
NameError: name 'job' is not defined
"""

The above exception was the direct cause of the following exception:

Traceback (most recent call last):
  File "D:\Python3.5.3\lib\concurrent\futures\_base.py", line 297, in _invoke_callbacks
    callback(self)
  File "deterministic_rule_pipeline.py", line 86, in store_result_csv_job
    results = future.result()
  File "D:\Python3.5.3\lib\concurrent\futures\_base.py", line 398, in result
    return self.__get_result()
  File "D:\Python3.5.3\lib\concurrent\futures\_base.py", line 357, in __get_result
    raise self._exception
NameError: name 'job' is not defined
2017-08-07 22:16:49  concurrent.futures ERROR      exception calling callback for <Future at 0x1b8dd63f390 state=finished raised NameError>
concurrent.futures.process._RemoteTraceback: 
"""
Traceback (most recent call last):
  File "D:\Python3.5.3\lib\concurrent\futures\process.py", line 175, in _process_worker
    r = call_item.fn(*call_item.args, **call_item.kwargs)
  File "C:\Users\alex\Desktop\pcm\deterministic method\pipeline\deterministic_rule_pipeline.py", line 62, in store_result_job
    if job == "p":
NameError: name 'job' is not defined
"""

The above exception was the direct cause of the following exception:

Traceback (most recent call last):
  File "D:\Python3.5.3\lib\concurrent\futures\_base.py", line 297, in _invoke_callbacks
    callback(self)
  File "deterministic_rule_pipeline.py", line 86, in store_result_csv_job
    results = future.result()
  File "D:\Python3.5.3\lib\concurrent\futures\_base.py", line 398, in result
    return self.__get_result()
  File "D:\Python3.5.3\lib\concurrent\futures\_base.py", line 357, in __get_result
    raise self._exception
NameError: name 'job' is not defined
2017-08-07 22:16:56  concurrent.futures ERROR      exception calling callback for <Future at 0x1b8dd63f438 state=finished raised NameError>
concurrent.futures.process._RemoteTraceback: 
"""
Traceback (most recent call last):
  File "D:\Python3.5.3\lib\concurrent\futures\process.py", line 175, in _process_worker
    r = call_item.fn(*call_item.args, **call_item.kwargs)
  File "C:\Users\alex\Desktop\pcm\deterministic method\pipeline\deterministic_rule_pipeline.py", line 62, in store_result_job
    if job == "p":
NameError: name 'job' is not defined
"""

The above exception was the direct cause of the following exception:

Traceback (most recent call last):
  File "D:\Python3.5.3\lib\concurrent\futures\_base.py", line 297, in _invoke_callbacks
    callback(self)
  File "deterministic_rule_pipeline.py", line 86, in store_result_csv_job
    results = future.result()
  File "D:\Python3.5.3\lib\concurrent\futures\_base.py", line 398, in result
    return self.__get_result()
  File "D:\Python3.5.3\lib\concurrent\futures\_base.py", line 357, in __get_result
    raise self._exception
NameError: name 'job' is not defined
2017-08-07 22:16:59  concurrent.futures ERROR      exception calling callback for <Future at 0x1b8dd63f4e0 state=finished raised NameError>
concurrent.futures.process._RemoteTraceback: 
"""
Traceback (most recent call last):
  File "D:\Python3.5.3\lib\concurrent\futures\process.py", line 175, in _process_worker
    r = call_item.fn(*call_item.args, **call_item.kwargs)
  File "C:\Users\alex\Desktop\pcm\deterministic method\pipeline\deterministic_rule_pipeline.py", line 62, in store_result_job
    if job == "p":
NameError: name 'job' is not defined
"""

The above exception was the direct cause of the following exception:

Traceback (most recent call last):
  File "D:\Python3.5.3\lib\concurrent\futures\_base.py", line 297, in _invoke_callbacks
    callback(self)
  File "deterministic_rule_pipeline.py", line 86, in store_result_csv_job
    results = future.result()
  File "D:\Python3.5.3\lib\concurrent\futures\_base.py", line 398, in result
    return self.__get_result()
  File "D:\Python3.5.3\lib\concurrent\futures\_base.py", line 357, in __get_result
    raise self._exception
NameError: name 'job' is not defined
2017-08-07 22:17:03  concurrent.futures ERROR      exception calling callback for <Future at 0x1b8dd63f588 state=finished raised NameError>
concurrent.futures.process._RemoteTraceback: 
"""
Traceback (most recent call last):
  File "D:\Python3.5.3\lib\concurrent\futures\process.py", line 175, in _process_worker
    r = call_item.fn(*call_item.args, **call_item.kwargs)
  File "C:\Users\alex\Desktop\pcm\deterministic method\pipeline\deterministic_rule_pipeline.py", line 62, in store_result_job
    if job == "p":
NameError: name 'job' is not defined
"""

The above exception was the direct cause of the following exception:

Traceback (most recent call last):
  File "D:\Python3.5.3\lib\concurrent\futures\_base.py", line 297, in _invoke_callbacks
    callback(self)
  File "deterministic_rule_pipeline.py", line 86, in store_result_csv_job
    results = future.result()
  File "D:\Python3.5.3\lib\concurrent\futures\_base.py", line 398, in result
    return self.__get_result()
  File "D:\Python3.5.3\lib\concurrent\futures\_base.py", line 357, in __get_result
    raise self._exception
NameError: name 'job' is not defined
2017-08-07 22:17:09  concurrent.futures ERROR      exception calling callback for <Future at 0x1b8dd63f630 state=finished raised NameError>
concurrent.futures.process._RemoteTraceback: 
"""
Traceback (most recent call last):
  File "D:\Python3.5.3\lib\concurrent\futures\process.py", line 175, in _process_worker
    r = call_item.fn(*call_item.args, **call_item.kwargs)
  File "C:\Users\alex\Desktop\pcm\deterministic method\pipeline\deterministic_rule_pipeline.py", line 62, in store_result_job
    if job == "p":
NameError: name 'job' is not defined
"""

The above exception was the direct cause of the following exception:

Traceback (most recent call last):
  File "D:\Python3.5.3\lib\concurrent\futures\_base.py", line 297, in _invoke_callbacks
    callback(self)
  File "deterministic_rule_pipeline.py", line 86, in store_result_csv_job
    results = future.result()
  File "D:\Python3.5.3\lib\concurrent\futures\_base.py", line 398, in result
    return self.__get_result()
  File "D:\Python3.5.3\lib\concurrent\futures\_base.py", line 357, in __get_result
    raise self._exception
NameError: name 'job' is not defined
2017-08-07 22:17:13  concurrent.futures ERROR      exception calling callback for <Future at 0x1b8dd63f780 state=finished raised NameError>
concurrent.futures.process._RemoteTraceback: 
"""
Traceback (most recent call last):
  File "D:\Python3.5.3\lib\concurrent\futures\process.py", line 175, in _process_worker
    r = call_item.fn(*call_item.args, **call_item.kwargs)
  File "C:\Users\alex\Desktop\pcm\deterministic method\pipeline\deterministic_rule_pipeline.py", line 62, in store_result_job
    if job == "p":
NameError: name 'job' is not defined
"""

The above exception was the direct cause of the following exception:

Traceback (most recent call last):
  File "D:\Python3.5.3\lib\concurrent\futures\_base.py", line 297, in _invoke_callbacks
    callback(self)
  File "deterministic_rule_pipeline.py", line 86, in store_result_csv_job
    results = future.result()
  File "D:\Python3.5.3\lib\concurrent\futures\_base.py", line 398, in result
    return self.__get_result()
  File "D:\Python3.5.3\lib\concurrent\futures\_base.py", line 357, in __get_result
    raise self._exception
NameError: name 'job' is not defined
2017-08-07 22:17:17  concurrent.futures ERROR      exception calling callback for <Future at 0x1b8dd63f6d8 state=finished raised NameError>
concurrent.futures.process._RemoteTraceback: 
"""
Traceback (most recent call last):
  File "D:\Python3.5.3\lib\concurrent\futures\process.py", line 175, in _process_worker
    r = call_item.fn(*call_item.args, **call_item.kwargs)
  File "C:\Users\alex\Desktop\pcm\deterministic method\pipeline\deterministic_rule_pipeline.py", line 62, in store_result_job
    if job == "p":
NameError: name 'job' is not defined
"""

The above exception was the direct cause of the following exception:

Traceback (most recent call last):
  File "D:\Python3.5.3\lib\concurrent\futures\_base.py", line 297, in _invoke_callbacks
    callback(self)
  File "deterministic_rule_pipeline.py", line 86, in store_result_csv_job
    results = future.result()
  File "D:\Python3.5.3\lib\concurrent\futures\_base.py", line 398, in result
    return self.__get_result()
  File "D:\Python3.5.3\lib\concurrent\futures\_base.py", line 357, in __get_result
    raise self._exception
NameError: name 'job' is not defined
2017-08-07 22:23:13  task  INFO       rule: txt\3_fields_process_dob\f_addr_middle.txt; pairs number: 6228
2017-08-07 22:23:13  task  INFO       rule: txt\3_fields_process_dob\l_middle_addr.txt; pairs number: 6080
2017-08-07 22:23:13  concurrent.futures ERROR      exception calling callback for <Future at 0x1add93f0c88 state=finished returned list>
Traceback (most recent call last):
  File "D:\Python3.5.3\lib\concurrent\futures\_base.py", line 297, in _invoke_callbacks
    callback(self)
  File "deterministic_rule_pipeline.py", line 101, in store_result_csv_job
    line1 = each[ : 19]
TypeError: 'datetime.datetime' object is not subscriptable
2017-08-07 22:23:13  concurrent.futures ERROR      exception calling callback for <Future at 0x1add93f0d30 state=finished returned list>
Traceback (most recent call last):
  File "D:\Python3.5.3\lib\concurrent\futures\_base.py", line 297, in _invoke_callbacks
    callback(self)
  File "deterministic_rule_pipeline.py", line 101, in store_result_csv_job
    line1 = each[ : 19]
TypeError: 'datetime.datetime' object is not subscriptable
2017-08-07 22:23:25  task  INFO       rule: txt\3_fields_process_dob\f_phone_middle.txt; pairs number: 9222
2017-08-07 22:23:25  task  INFO       rule: txt\3_fields_process_dob\f_ssn_addr.txt; pairs number: 11060
2017-08-07 22:23:25  concurrent.futures ERROR      exception calling callback for <Future at 0x1add93f0be0 state=finished returned list>
Traceback (most recent call last):
  File "D:\Python3.5.3\lib\concurrent\futures\_base.py", line 297, in _invoke_callbacks
    callback(self)
  File "deterministic_rule_pipeline.py", line 101, in store_result_csv_job
    line1 = each[ : 19]
TypeError: 'datetime.datetime' object is not subscriptable
2017-08-07 22:23:25  concurrent.futures ERROR      exception calling callback for <Future at 0x1add93b00b8 state=finished returned list>
Traceback (most recent call last):
  File "D:\Python3.5.3\lib\concurrent\futures\_base.py", line 297, in _invoke_callbacks
    callback(self)
  File "deterministic_rule_pipeline.py", line 101, in store_result_csv_job
    line1 = each[ : 19]
TypeError: 'datetime.datetime' object is not subscriptable
2017-08-07 22:23:39  task  INFO       rule: txt\3_fields_process_dob\gender_ssn_phone.txt; pairs number: 6816
2017-08-07 22:23:39  concurrent.futures ERROR      exception calling callback for <Future at 0x1add93f0e80 state=finished returned list>
Traceback (most recent call last):
  File "D:\Python3.5.3\lib\concurrent\futures\_base.py", line 297, in _invoke_callbacks
    callback(self)
  File "deterministic_rule_pipeline.py", line 101, in store_result_csv_job
    line1 = each[ : 19]
TypeError: 'datetime.datetime' object is not subscriptable
2017-08-07 22:23:44  task  INFO       rule: txt\3_fields_process_dob\l_middle_ssn.txt; pairs number: 5722
2017-08-07 22:23:44  concurrent.futures ERROR      exception calling callback for <Future at 0x1add93f0fd0 state=finished returned list>
Traceback (most recent call last):
  File "D:\Python3.5.3\lib\concurrent\futures\_base.py", line 297, in _invoke_callbacks
    callback(self)
  File "deterministic_rule_pipeline.py", line 101, in store_result_csv_job
    line1 = each[ : 19]
TypeError: 'datetime.datetime' object is not subscriptable
2017-08-07 22:23:52  task  INFO       rule: txt\3_fields_process_dob\l_ssn_phone.txt; pairs number: 6670
2017-08-07 22:23:52  concurrent.futures ERROR      exception calling callback for <Future at 0x1add93f0f28 state=finished returned list>
Traceback (most recent call last):
  File "D:\Python3.5.3\lib\concurrent\futures\_base.py", line 297, in _invoke_callbacks
    callback(self)
  File "deterministic_rule_pipeline.py", line 101, in store_result_csv_job
    line1 = each[ : 19]
TypeError: 'NoneType' object is not subscriptable
2017-08-07 22:23:59  task  INFO       rule: txt\3_fields_process_dob\f_ssn_phone.txt; pairs number: 7348
2017-08-07 22:24:00  concurrent.futures ERROR      exception calling callback for <Future at 0x1add94000b8 state=finished returned list>
Traceback (most recent call last):
  File "D:\Python3.5.3\lib\concurrent\futures\_base.py", line 297, in _invoke_callbacks
    callback(self)
  File "deterministic_rule_pipeline.py", line 101, in store_result_csv_job
    line1 = each[ : 19]
TypeError: 'datetime.datetime' object is not subscriptable
2017-08-07 22:24:06  task  INFO       rule: txt\3_fields_process_dob\f_ssn_email.txt; pairs number: 0
2017-08-07 22:24:16  task  INFO       rule: txt\3_fields_process_dob\gender_ssn_addr.txt; pairs number: 10252
2017-08-07 22:24:17  concurrent.futures ERROR      exception calling callback for <Future at 0x1add9400160 state=finished returned list>
Traceback (most recent call last):
  File "D:\Python3.5.3\lib\concurrent\futures\_base.py", line 297, in _invoke_callbacks
    callback(self)
  File "deterministic_rule_pipeline.py", line 101, in store_result_csv_job
    line1 = each[ : 19]
TypeError: 'datetime.datetime' object is not subscriptable
2017-08-07 22:24:20  task  INFO       rule: txt\3_fields_process_dob\f_l_ssn.txt; pairs number: 32612
2017-08-07 22:24:21  concurrent.futures ERROR      exception calling callback for <Future at 0x1add93f0dd8 state=finished returned list>
Traceback (most recent call last):
  File "D:\Python3.5.3\lib\concurrent\futures\_base.py", line 297, in _invoke_callbacks
    callback(self)
  File "deterministic_rule_pipeline.py", line 101, in store_result_csv_job
    line1 = each[ : 19]
TypeError: 'datetime.datetime' object is not subscriptable
2017-08-07 22:24:22  task  INFO       rule: txt\3_fields_process_dob\l_middle_phone.txt; pairs number: 10712
2017-08-07 22:24:22  concurrent.futures ERROR      exception calling callback for <Future at 0x1add9400358 state=finished returned list>
Traceback (most recent call last):
  File "D:\Python3.5.3\lib\concurrent\futures\_base.py", line 297, in _invoke_callbacks
    callback(self)
  File "deterministic_rule_pipeline.py", line 101, in store_result_csv_job
    line1 = each[ : 19]
TypeError: 'datetime.datetime' object is not subscriptable
2017-08-07 22:24:34  task  INFO       rule: txt\3_fields_process_dob\gender_phone_addr.txt; pairs number: 15288
2017-08-07 22:24:35  concurrent.futures ERROR      exception calling callback for <Future at 0x1add9400208 state=finished returned list>
Traceback (most recent call last):
  File "D:\Python3.5.3\lib\concurrent\futures\_base.py", line 297, in _invoke_callbacks
    callback(self)
  File "deterministic_rule_pipeline.py", line 101, in store_result_csv_job
    line1 = each[ : 19]
TypeError: 'datetime.datetime' object is not subscriptable
2017-08-07 22:24:46  task  INFO       rule: txt\3_fields_process_dob\f_addr_phone.txt; pairs number: 13446
2017-08-07 22:24:47  concurrent.futures ERROR      exception calling callback for <Future at 0x1add9400550 state=finished returned list>
Traceback (most recent call last):
  File "D:\Python3.5.3\lib\concurrent\futures\_base.py", line 297, in _invoke_callbacks
    callback(self)
  File "deterministic_rule_pipeline.py", line 101, in store_result_csv_job
    line1 = each[ : 19]
TypeError: 'datetime.datetime' object is not subscriptable
2017-08-07 22:24:57  task  INFO       rule: txt\3_fields_process_dob\f_l_addr.txt; pairs number: 24920
2017-08-07 22:24:58  concurrent.futures ERROR      exception calling callback for <Future at 0x1add9400400 state=finished returned list>
Traceback (most recent call last):
  File "D:\Python3.5.3\lib\concurrent\futures\_base.py", line 297, in _invoke_callbacks
    callback(self)
  File "deterministic_rule_pipeline.py", line 101, in store_result_csv_job
    line2 = result[19 : ]
TypeError: 'datetime.datetime' object is not subscriptable
2017-08-07 22:25:07  task  INFO       rule: txt\3_fields_process_dob\l_ssn_addr.txt; pairs number: 11146
2017-08-07 22:25:07  concurrent.futures ERROR      exception calling callback for <Future at 0x1add94006a0 state=finished returned list>
Traceback (most recent call last):
  File "D:\Python3.5.3\lib\concurrent\futures\_base.py", line 297, in _invoke_callbacks
    callback(self)
  File "deterministic_rule_pipeline.py", line 101, in store_result_csv_job
    line2 = result[19 : ]
TypeError: 'datetime.datetime' object is not subscriptable
2017-08-07 22:25:29  task  INFO       rule: txt\3_fields_process_dob\l_gender_addr.txt; pairs number: 55394
2017-08-07 22:25:31  concurrent.futures ERROR      exception calling callback for <Future at 0x1add94004a8 state=finished returned list>
Traceback (most recent call last):
  File "D:\Python3.5.3\lib\concurrent\futures\_base.py", line 297, in _invoke_callbacks
    callback(self)
  File "deterministic_rule_pipeline.py", line 101, in store_result_csv_job
    line2 = result[19 : ]
TypeError: 'NoneType' object is not subscriptable
2017-08-07 22:25:54  task  INFO       rule: txt\3_fields_process_dob\f_l_phone.txt; pairs number: 44294
2017-08-07 22:25:56  concurrent.futures ERROR      exception calling callback for <Future at 0x1add9400748 state=finished returned list>
Traceback (most recent call last):
  File "D:\Python3.5.3\lib\concurrent\futures\_base.py", line 297, in _invoke_callbacks
    callback(self)
  File "deterministic_rule_pipeline.py", line 101, in store_result_csv_job
    line2 = result[19 : ]
TypeError: 'NoneType' object is not subscriptable
2017-08-07 22:26:05  task  INFO       rule: txt\3_fields_process_dob\l_gender_ssn.txt; pairs number: 28426
2017-08-07 22:26:06  concurrent.futures ERROR      exception calling callback for <Future at 0x1add9400898 state=finished returned list>
Traceback (most recent call last):
  File "D:\Python3.5.3\lib\concurrent\futures\_base.py", line 297, in _invoke_callbacks
    callback(self)
  File "deterministic_rule_pipeline.py", line 101, in store_result_csv_job
    line2 = result[19 : ]
TypeError: 'datetime.datetime' object is not subscriptable
2017-08-07 22:26:20  task  INFO       rule: txt\3_fields_process_dob\f_l_middle.txt; pairs number: 20986
2017-08-07 22:26:20  concurrent.futures ERROR      exception calling callback for <Future at 0x1add9400940 state=finished returned list>
Traceback (most recent call last):
  File "D:\Python3.5.3\lib\concurrent\futures\_base.py", line 297, in _invoke_callbacks
    callback(self)
  File "deterministic_rule_pipeline.py", line 101, in store_result_csv_job
    line2 = result[19 : ]
TypeError: 'NoneType' object is not subscriptable
2017-08-07 22:26:27  task  INFO       rule: txt\3_fields_process_dob\l_addr_phone.txt; pairs number: 15542
2017-08-07 22:26:28  concurrent.futures ERROR      exception calling callback for <Future at 0x1add94009e8 state=finished returned list>
Traceback (most recent call last):
  File "D:\Python3.5.3\lib\concurrent\futures\_base.py", line 297, in _invoke_callbacks
    callback(self)
  File "deterministic_rule_pipeline.py", line 101, in store_result_csv_job
    line2 = result[19 : ]
TypeError: 'datetime.datetime' object is not subscriptable
2017-08-07 22:29:41  task  INFO       rule: txt\3_fields_process_dob\f_gender_email.txt; pairs number: 306294
2017-08-07 22:29:53  concurrent.futures ERROR      exception calling callback for <Future at 0x1add94007f0 state=finished returned list>
Traceback (most recent call last):
  File "D:\Python3.5.3\lib\concurrent\futures\_base.py", line 297, in _invoke_callbacks
    callback(self)
  File "deterministic_rule_pipeline.py", line 101, in store_result_csv_job
    line2 = result[19 : ]
TypeError: 'datetime.datetime' object is not subscriptable
2017-08-07 22:44:40  task  INFO       rule: txt\3_fields_process_dob\f_l_gender.txt; pairs number: 1408314
2017-08-07 22:45:47  concurrent.futures ERROR      exception calling callback for <Future at 0x1add94005f8 state=finished returned list>
Traceback (most recent call last):
  File "D:\Python3.5.3\lib\concurrent\futures\_base.py", line 297, in _invoke_callbacks
    callback(self)
  File "deterministic_rule_pipeline.py", line 101, in store_result_csv_job
    line2 = result[19 : ]
TypeError: 'datetime.datetime' object is not subscriptable
2017-08-07 22:53:02  task  INFO       rule: txt\3_fields_process_dob\f_phone_middle.txt; pairs number: 9222
2017-08-07 22:53:09  task  INFO       rule: txt\3_fields_process_dob\gender_phone_addr.txt; pairs number: 15288
2017-08-07 22:53:21  task  INFO       rule: txt\3_fields_process_dob\l_gender_ssn.txt; pairs number: 28426
2017-08-07 22:53:21  task  INFO       rule: txt\3_fields_process_dob\f_ssn_addr.txt; pairs number: 11060
2017-08-07 22:53:37  task  INFO       rule: txt\3_fields_process_dob\f_l_middle.txt; pairs number: 20986
2017-08-07 22:53:38  task  INFO       rule: txt\3_fields_process_dob\f_ssn_phone.txt; pairs number: 7348
2017-08-07 22:53:59  task  INFO       rule: txt\3_fields_process_dob\f_l_addr.txt; pairs number: 24920
2017-08-07 22:54:00  task  INFO       rule: txt\3_fields_process_dob\l_addr_phone.txt; pairs number: 15542
2017-08-07 22:54:16  task  INFO       rule: txt\3_fields_process_dob\l_ssn_phone.txt; pairs number: 6670
2017-08-07 22:54:18  task  INFO       rule: txt\3_fields_process_dob\l_middle_phone.txt; pairs number: 10712
2017-08-07 22:54:27  task  INFO       rule: txt\3_fields_process_dob\f_l_phone.txt; pairs number: 44294
2017-08-07 22:54:34  task  INFO       rule: txt\3_fields_process_dob\f_ssn_email.txt; pairs number: 0
2017-08-07 22:54:36  task  INFO       rule: txt\3_fields_process_dob\l_middle_addr.txt; pairs number: 6080
2017-08-07 22:54:54  task  INFO       rule: txt\3_fields_process_dob\f_addr_phone.txt; pairs number: 13446
2017-08-07 22:54:55  task  INFO       rule: txt\3_fields_process_dob\l_ssn_addr.txt; pairs number: 11146
2017-08-07 22:55:09  task  INFO       rule: txt\3_fields_process_dob\f_l_ssn.txt; pairs number: 32612
2017-08-07 22:55:09  task  INFO       rule: txt\3_fields_process_dob\f_addr_middle.txt; pairs number: 6228
2017-08-07 22:55:18  task  INFO       rule: txt\3_fields_process_dob\gender_ssn_phone.txt; pairs number: 6816
2017-08-07 22:55:24  task  INFO       rule: txt\3_fields_process_dob\l_middle_ssn.txt; pairs number: 5722
2017-08-07 22:55:34  task  INFO       rule: txt\3_fields_process_dob\gender_ssn_addr.txt; pairs number: 10252
2017-08-07 22:56:07  task  INFO       rule: txt\3_fields_process_dob\l_gender_addr.txt; pairs number: 55394
2017-08-07 23:12:55  task  INFO       rule: txt\3_fields_process_dob\f_l_gender.txt; pairs number: 1408314
2017-08-07 23:18:25  task  INFO       rule: txt\3_fields_process_dob\l_middle_addr.txt; pairs number: 6080
2017-08-07 23:21:58  task  INFO       rule: txt\3_fields_process_dob\f_phone_middle.txt; pairs number: 9222
2017-08-07 23:22:02  task  INFO       rule: txt\3_fields_process_dob\gender_ssn_addr.txt; pairs number: 10252
2017-08-07 23:22:02  task  INFO       rule: txt\3_fields_process_dob\gender_ssn_phone.txt; pairs number: 6816
2017-08-07 23:22:20  task  INFO       rule: txt\3_fields_process_dob\l_middle_addr.txt; pairs number: 6080
2017-08-07 23:22:24  task  INFO       rule: txt\3_fields_process_dob\f_l_middle.txt; pairs number: 20986
2017-08-07 23:22:36  task  INFO       rule: txt\3_fields_process_dob\f_ssn_phone.txt; pairs number: 7348
2017-08-07 23:22:41  task  INFO       rule: txt\3_fields_process_dob\f_addr_phone.txt; pairs number: 13446
2017-08-07 23:22:46  task  INFO       rule: txt\3_fields_process_dob\l_ssn_phone.txt; pairs number: 6670
2017-08-07 23:22:54  task  INFO       rule: txt\3_fields_process_dob\f_addr_middle.txt; pairs number: 6228
2017-08-07 23:22:59  task  INFO       rule: txt\3_fields_process_dob\f_ssn_email.txt; pairs number: 0
2017-08-07 23:23:14  task  INFO       rule: txt\3_fields_process_dob\l_gender_ssn.txt; pairs number: 28426
2017-08-07 23:23:18  task  INFO       rule: txt\3_fields_process_dob\l_addr_phone.txt; pairs number: 15542
2017-08-07 23:23:34  task  INFO       rule: txt\3_fields_process_dob\gender_phone_addr.txt; pairs number: 15288
2017-08-07 23:23:38  task  INFO       rule: txt\3_fields_process_dob\f_l_ssn.txt; pairs number: 32612
2017-08-07 23:23:41  task  INFO       rule: txt\3_fields_process_dob\f_ssn_addr.txt; pairs number: 11060
2017-08-07 23:23:58  task  INFO       rule: txt\3_fields_process_dob\l_middle_phone.txt; pairs number: 10712
2017-08-07 23:24:05  task  INFO       rule: txt\3_fields_process_dob\l_ssn_addr.txt; pairs number: 11146
2017-08-07 23:24:13  task  INFO       rule: txt\3_fields_process_dob\l_middle_ssn.txt; pairs number: 5722
2017-08-07 23:24:27  task  INFO       rule: txt\3_fields_process_dob\f_l_phone.txt; pairs number: 44294
2017-08-07 23:24:51  task  INFO       rule: txt\3_fields_process_dob\l_gender_addr.txt; pairs number: 55394
2017-08-07 23:24:52  task  INFO       rule: txt\3_fields_process_dob\f_l_addr.txt; pairs number: 24920
2017-08-07 23:29:07  sqlalchemy.pool.QueuePool ERROR      Exception during reset or similar
Traceback (most recent call last):
  File "D:\Python3.5.3\lib\site-packages\sqlalchemy\pool.py", line 687, in _finalize_fairy
    fairy._reset(pool)
  File "D:\Python3.5.3\lib\site-packages\sqlalchemy\pool.py", line 829, in _reset
    pool._dialect.do_rollback(self)
  File "D:\Python3.5.3\lib\site-packages\sqlalchemy\engine\default.py", line 440, in do_rollback
    dbapi_connection.rollback()
KeyboardInterrupt
2017-08-07 23:29:07  sqlalchemy.pool.QueuePool ERROR      Exception during reset or similar
Traceback (most recent call last):
  File "D:\Python3.5.3\lib\site-packages\sqlalchemy\pool.py", line 687, in _finalize_fairy
    fairy._reset(pool)
  File "D:\Python3.5.3\lib\site-packages\sqlalchemy\pool.py", line 829, in _reset
    pool._dialect.do_rollback(self)
  File "D:\Python3.5.3\lib\site-packages\sqlalchemy\engine\default.py", line 440, in do_rollback
    dbapi_connection.rollback()
cx_Oracle.InterfaceError: not connected
2017-08-07 23:30:34  task  INFO       rule: txt\3_fields_process_dob\l_middle_ssn.txt; pairs number: 5722
2017-08-07 23:30:43  task  INFO       rule: txt\3_fields_process_dob\l_ssn_addr.txt; pairs number: 11146
2017-08-07 23:30:49  task  INFO       rule: txt\3_fields_process_dob\gender_ssn_phone.txt; pairs number: 6816
2017-08-07 23:30:54  task  INFO       rule: txt\3_fields_process_dob\l_middle_addr.txt; pairs number: 6080
2017-08-07 23:31:02  task  INFO       rule: txt\3_fields_process_dob\f_addr_middle.txt; pairs number: 6228
2017-08-07 23:31:08  task  INFO       rule: txt\3_fields_process_dob\l_middle_phone.txt; pairs number: 10712
2017-08-07 23:31:16  task  INFO       rule: txt\3_fields_process_dob\f_l_phone.txt; pairs number: 44294
2017-08-07 23:31:19  task  INFO       rule: txt\3_fields_process_dob\gender_ssn_addr.txt; pairs number: 10252
2017-08-07 23:31:30  task  INFO       rule: txt\3_fields_process_dob\f_phone_middle.txt; pairs number: 9222
2017-08-07 23:31:41  task  INFO       rule: txt\3_fields_process_dob\l_addr_phone.txt; pairs number: 15542
2017-08-07 23:31:42  task  INFO       rule: txt\3_fields_process_dob\gender_phone_addr.txt; pairs number: 15288
2017-08-07 23:31:54  task  INFO       rule: txt\3_fields_process_dob\f_addr_phone.txt; pairs number: 13446
2017-08-07 23:32:05  task  INFO       rule: txt\3_fields_process_dob\f_ssn_addr.txt; pairs number: 11060
2017-08-07 23:32:09  task  INFO       rule: txt\3_fields_process_dob\f_ssn_email.txt; pairs number: 0
2017-08-07 23:32:16  task  INFO       rule: txt\3_fields_process_dob\f_l_addr.txt; pairs number: 24920
2017-08-07 23:32:23  task  INFO       rule: txt\3_fields_process_dob\f_l_middle.txt; pairs number: 20986
2017-08-07 23:32:25  task  INFO       rule: txt\3_fields_process_dob\f_ssn_phone.txt; pairs number: 7348
2017-08-07 23:32:31  task  INFO       rule: txt\3_fields_process_dob\l_gender_ssn.txt; pairs number: 28426
2017-08-07 23:32:41  task  INFO       rule: txt\3_fields_process_dob\l_ssn_phone.txt; pairs number: 6670
2017-08-07 23:33:02  task  INFO       rule: txt\3_fields_process_dob\f_l_ssn.txt; pairs number: 32612
2017-08-07 23:33:09  task  INFO       rule: txt\3_fields_process_dob\l_gender_addr.txt; pairs number: 55394
2017-08-08 09:31:41  task  INFO       rule: txt\3_fields_process_dob\l_ssn_addr.txt; pairs number: 11146
2017-08-08 09:32:00  task  INFO       rule: txt\3_fields_process_dob\f_l_middle.txt; pairs number: 20986
2017-08-08 09:32:01  task  INFO       rule: txt\3_fields_process_dob\l_gender_ssn.txt; pairs number: 28426
2017-08-08 09:32:13  task  INFO       rule: txt\3_fields_process_dob\f_addr_phone.txt; pairs number: 13446
2017-08-08 09:32:20  task  INFO       rule: txt\3_fields_process_dob\l_middle_phone.txt; pairs number: 10712
2017-08-08 09:32:28  task  INFO       rule: txt\3_fields_process_dob\l_ssn_phone.txt; pairs number: 6670
2017-08-08 09:32:31  task  INFO       rule: txt\3_fields_process_dob\f_l_phone.txt; pairs number: 44294
2017-08-08 09:32:36  task  INFO       rule: txt\3_fields_process_dob\gender_ssn_addr.txt; pairs number: 10252
2017-08-08 09:32:36  task  INFO       rule: txt\3_fields_process_dob\f_addr_middle.txt; pairs number: 6228
2017-08-08 09:32:52  task  INFO       rule: txt\3_fields_process_dob\l_middle_ssn.txt; pairs number: 5722
2017-08-08 09:33:01  task  INFO       rule: txt\3_fields_process_dob\f_phone_middle.txt; pairs number: 9222
2017-08-08 09:33:10  task  INFO       rule: txt\3_fields_process_dob\l_addr_phone.txt; pairs number: 15542
2017-08-08 09:33:14  task  INFO       rule: txt\3_fields_process_dob\gender_ssn_phone.txt; pairs number: 6816
2017-08-08 09:33:25  task  INFO       rule: txt\3_fields_process_dob\f_l_addr.txt; pairs number: 24920
2017-08-08 09:33:32  task  INFO       rule: txt\3_fields_process_dob\l_middle_addr.txt; pairs number: 6080
2017-08-08 09:33:40  task  INFO       rule: txt\3_fields_process_dob\f_l_ssn.txt; pairs number: 32612
2017-08-08 09:33:40  task  INFO       rule: txt\3_fields_process_dob\gender_phone_addr.txt; pairs number: 15288
2017-08-08 09:33:51  task  INFO       rule: txt\3_fields_process_dob\f_ssn_email.txt; pairs number: 0
2017-08-08 09:33:54  task  INFO       rule: txt\3_fields_process_dob\f_ssn_phone.txt; pairs number: 7348
2017-08-08 09:34:02  task  INFO       rule: txt\3_fields_process_dob\f_ssn_addr.txt; pairs number: 11060
2017-08-08 09:34:26  task  INFO       rule: txt\3_fields_process_dob\l_gender_addr.txt; pairs number: 55394
